2021-06-24 05:20:23,525 INFO * Creating the SAH node usb image.
2021-06-24 05:20:23,528 ERROR Traceback (most recent call last):
  File "setup_usb_idrac.py", line 54, in setup
    args, ignore = parser.parse_known_args()
  File "/usr/lib64/python3.6/argparse.py", line 1766, in parse_known_args
    namespace, args = self._parse_known_args(args, namespace)
  File "/usr/lib64/python3.6/argparse.py", line 2001, in _parse_known_args
    ', '.join(required_actions))
  File "/usr/lib64/python3.6/argparse.py", line 2393, in error
    self.exit(2, _('%(prog)s: error: %(message)s\n') % args)
  File "/usr/lib64/python3.6/argparse.py", line 2380, in exit
    _sys.exit(status)
SystemExit: 2

2021-06-24 05:20:23,528 ERROR <class 'SystemExit'>
2021-06-24 05:26:13,086 INFO * Creating the SAH node usb image.
2021-06-24 05:26:13,089 ERROR Traceback (most recent call last):
  File "setup_usb_idrac.py", line 54, in setup
    args, ignore = parser.parse_known_args()
  File "/usr/lib64/python3.6/argparse.py", line 1766, in parse_known_args
    namespace, args = self._parse_known_args(args, namespace)
  File "/usr/lib64/python3.6/argparse.py", line 2001, in _parse_known_args
    ', '.join(required_actions))
  File "/usr/lib64/python3.6/argparse.py", line 2393, in error
    self.exit(2, _('%(prog)s: error: %(message)s\n') % args)
  File "/usr/lib64/python3.6/argparse.py", line 2380, in exit
    _sys.exit(status)
SystemExit: 2

2021-06-24 05:26:13,089 ERROR <class 'SystemExit'>
2021-06-24 05:26:31,585 INFO * Creating the SAH node usb image.
2021-06-24 05:26:31,587 ERROR Traceback (most recent call last):
  File "setup_usb_idrac.py", line 62, in setup
    "an idrac virtual media image")
AssertionError: You need to spefify the type of installation to perform 
-usb_key devideID if using a physical key
-idrac_vmedia_img if using an idrac virtual media image

2021-06-24 05:26:31,587 ERROR <class 'AssertionError'>
2021-06-24 05:26:40,014 INFO * Creating the SAH node usb image.
2021-06-24 05:26:40,015 DEBUG loading settings files /root/r87.ini
2021-06-24 05:26:40,015 ERROR Traceback (most recent call last):
  File "setup_usb_idrac.py", line 65, in setup
    settings = Settings(args.settings)
NameError: name 'Settings' is not defined

2021-06-24 05:26:40,015 ERROR <class 'NameError'>
2021-06-24 05:27:09,802 INFO * Creating the SAH node usb image.
2021-06-24 05:27:09,804 DEBUG loading settings files /root/r87.ini
2021-06-24 05:27:09,804 ERROR Traceback (most recent call last):
  File "setup_usb_idrac.py", line 65, in setup
    settings = Settings(args.settings)
  File "/home/ansible/JetPack/src/deploy/ocp_deployer/settings/ocp_config.py", line 31, in __init__
    settings_file), settings_file + " file does not exist"
AssertionError: /root/r87.ini file does not exist

2021-06-24 05:27:09,804 ERROR <class 'AssertionError'>
2021-06-24 05:28:07,124 INFO * Creating the SAH node usb image.
2021-06-24 05:28:07,126 DEBUG loading settings files /root/r87.ini
2021-06-24 05:28:07,126 ERROR Traceback (most recent call last):
  File "setup_usb_idrac.py", line 65, in setup
    settings = Settings(args.settings)
  File "/home/ansible/JetPack/src/deploy/ocp_deployer/settings/ocp_config.py", line 31, in __init__
    settings_file), settings_file + " file does not exist"
AssertionError: /root/r87.ini file does not exist

2021-06-24 05:28:07,126 ERROR <class 'AssertionError'>
2021-06-24 05:28:16,843 INFO * Creating the SAH node usb image.
2021-06-24 05:28:16,845 DEBUG loading settings files /home/ansible/r87.ini
2021-06-24 05:28:16,846 ERROR Traceback (most recent call last):
  File "setup_usb_idrac.py", line 65, in setup
    settings = Settings(args.settings)
  File "/home/ansible/JetPack/src/deploy/ocp_deployer/settings/ocp_config.py", line 63, in __init__
    self.pull_secret_file=deploy_settings['pull_secret_file']
KeyError: 'pull_secret_file'

2021-06-24 05:28:16,846 ERROR <class 'KeyError'>
2021-06-24 05:30:01,979 INFO * Creating the SAH node usb image.
2021-06-24 05:30:01,980 DEBUG loading settings files /home/ansible/r87.ini
2021-06-24 05:30:01,981 ERROR Traceback (most recent call last):
  File "setup_usb_idrac.py", line 65, in setup
    settings = Settings(args.settings)
  File "/home/ansible/JetPack/src/deploy/ocp_deployer/settings/ocp_config.py", line 70, in __init__
    with open(self.nodes_yaml, 'r') as file:
FileNotFoundError: [Errno 2] No such file or directory: '/home/ansible/JetPack/src/deploy/ocp_deployer/nodes.yaml'

2021-06-24 05:30:01,981 ERROR <class 'FileNotFoundError'>
2021-06-24 08:40:10,063 INFO * Creating the SAH node usb image.
2021-06-24 08:40:10,065 DEBUG loading settings files /home/ansible/r87.ini
2021-06-24 08:40:10,066 ERROR Traceback (most recent call last):
  File "setup_usb_idrac.py", line 65, in setup
    settings = Settings(args.settings)
  File "/home/ansible/JetPack/src/deploy/ocp_deployer/settings/ocp_config.py", line 70, in __init__
    with open(self.nodes_yaml, 'r') as file:
FileNotFoundError: [Errno 2] No such file or directory: '/home/ansible/JetPack/src/deploy/ocp_deployer/nodes.yaml'

2021-06-24 08:40:10,066 ERROR <class 'FileNotFoundError'>
2021-06-24 08:42:27,587 INFO * Creating the SAH node usb image.
2021-06-24 08:42:27,588 DEBUG loading settings files /home/ansible/r87.ini
2021-06-24 08:42:27,589 ERROR Traceback (most recent call last):
  File "setup_usb_idrac.py", line 65, in setup
    settings = Settings(args.settings)
  File "/home/ansible/JetPack/src/deploy/ocp_deployer/settings/ocp_config.py", line 70, in __init__
    with open(self.nodes_yaml, 'r') as file:
FileNotFoundError: [Errno 2] No such file or directory: '/home/ansible/nodes.yaml'

2021-06-24 08:42:27,589 ERROR <class 'FileNotFoundError'>
2021-06-24 08:46:08,901 INFO * Creating the SAH node usb image.
2021-06-24 08:46:08,902 DEBUG loading settings files /home/ansible/r87.ini
2021-06-24 08:46:08,911 INFO Settings .ini: /home/ansible/r87.ini
2021-06-24 08:46:08,911 ERROR Traceback (most recent call last):
  File "setup_usb_idrac.py", line 67, in setup
    logger.info("Settings .properties " + settings.network_conf)
AttributeError: 'OCP_Settings' object has no attribute 'network_conf'

2021-06-24 08:46:08,911 ERROR <class 'AttributeError'>
2021-06-24 08:51:38,392 INFO * Creating the SAH node usb image.
2021-06-24 08:51:38,393 DEBUG loading settings files /home/ansible/r87.ini
2021-06-24 08:51:38,401 INFO Settings .ini: /home/ansible/r87.ini
2021-06-24 08:51:38,401 INFO Settings .yaml /home/ansible/nodes.yaml
2021-06-24 08:51:38,402 ERROR Traceback (most recent call last):
  File "setup_usb_idrac.py", line 70, in setup
    rhel_iso = settings.rhel_iso
AttributeError: 'OCP_Settings' object has no attribute 'rhel_iso'

2021-06-24 08:51:38,402 ERROR <class 'AttributeError'>
2021-06-24 08:53:48,077 INFO * Creating the SAH node usb image.
2021-06-24 08:53:48,078 DEBUG loading settings files /home/ansible/r87.ini
2021-06-24 08:53:48,086 INFO Settings .ini: /home/ansible/r87.ini
2021-06-24 08:53:48,086 INFO Settings .yaml /home/ansible/nodes.yaml
2021-06-24 08:53:48,087 ERROR Traceback (most recent call last):
  File "setup_usb_idrac.py", line 70, in setup
    rhel_iso = settings.rhel_iso
AttributeError: 'OCP_Settings' object has no attribute 'rhel_iso'

2021-06-24 08:53:48,087 ERROR <class 'AttributeError'>
2021-06-24 09:04:48,424 INFO * Creating the SAH node usb image.
2021-06-24 09:04:48,426 DEBUG loading settings files /home/ansible/r87.ini
2021-06-24 09:04:48,427 ERROR Traceback (most recent call last):
  File "setup_usb_idrac.py", line 65, in setup
    settings = Settings(args.settings)
  File "/home/ansible/JetPack/src/deploy/ocp_deployer/settings/ocp_config.py", line 46, in __init__
    self.rhel_iso = dev_settings['rhel_iso']
NameError: name 'dev_settings' is not defined

2021-06-24 09:04:48,427 ERROR <class 'NameError'>
2021-06-24 09:07:52,436 INFO * Creating the SAH node usb image.
2021-06-24 09:07:52,437 DEBUG loading settings files /home/ansible/r87.ini
2021-06-24 09:07:52,460 ERROR Traceback (most recent call last):
  File "setup_usb_idrac.py", line 65, in setup
    settings = Settings(args.settings)
  File "/home/ansible/JetPack/src/deploy/ocp_deployer/settings/ocp_config.py", line 47, in __init__
    "Development settings")
  File "/home/ansible/JetPack/src/deploy/ocp_deployer/settings/ocp_config.py", line 90, in get_settings_section
    options = self.conf.options(section)
  File "/usr/lib64/python3.6/configparser.py", line 675, in options
    raise NoSectionError(section) from None
configparser.NoSectionError: No section: 'Development settings'

2021-06-24 09:07:52,460 ERROR <class 'configparser.NoSectionError'>
2021-06-24 09:08:29,632 INFO * Creating the SAH node usb image.
2021-06-24 09:08:29,633 DEBUG loading settings files /home/ansible/r87.ini
2021-06-24 09:08:29,641 INFO Settings .ini: /home/ansible/r87.ini
2021-06-24 09:08:29,641 INFO Settings .yaml /home/ansible/nodes.yaml
2021-06-24 09:08:29,642 ERROR Traceback (most recent call last):
  File "setup_usb_idrac.py", line 73, in setup
    sah = Sah()
NameError: name 'Sah' is not defined

2021-06-24 09:08:29,642 ERROR <class 'NameError'>
2021-06-24 09:08:55,021 INFO * Creating the SAH node usb image.
2021-06-24 09:08:55,023 DEBUG loading settings files /home/ansible/r87.ini
2021-06-24 09:08:55,031 INFO Settings .ini: /home/ansible/r87.ini
2021-06-24 09:08:55,031 INFO Settings .yaml /home/ansible/nodes.yaml
2021-06-24 09:08:55,032 ERROR Traceback (most recent call last):
  File "setup_usb_idrac.py", line 74, in setup
    sah.update_kickstart_usb()
AttributeError: 'CSah' object has no attribute 'update_kickstart_usb'

2021-06-24 09:08:55,032 ERROR <class 'AttributeError'>
2021-06-24 09:35:51,048 INFO * Creating the SAH node usb image.
2021-06-24 09:35:51,050 DEBUG loading settings files /home/ansible/r87.ini
2021-06-24 09:35:51,058 INFO Settings .ini: /home/ansible/r87.ini
2021-06-24 09:35:51,058 INFO Settings .yaml /home/ansible/nodes.yaml
2021-06-24 09:35:51,058 ERROR Traceback (most recent call last):
  File "setup_usb_idrac.py", line 74, in setup
    sah.update_kickstart_usb()
  File "/home/ansible/JetPack/src/deploy/ocp_deployer/csah.py", line 299, in update_kickstart_usb
    tester = Checkpoints()
NameError: name 'Checkpoints' is not defined

2021-06-24 09:35:51,059 ERROR <class 'NameError'>
2021-06-24 09:38:17,965 INFO * Creating the SAH node usb image.
2021-06-24 09:38:17,967 DEBUG loading settings files /home/ansible/r87.ini
2021-06-24 09:38:17,975 INFO Settings .ini: /home/ansible/r87.ini
2021-06-24 09:38:17,975 INFO Settings .yaml /home/ansible/nodes.yaml
2021-06-24 09:38:17,975 ERROR Traceback (most recent call last):
  File "setup_usb_idrac.py", line 74, in setup
    sah.update_kickstart_usb()
  File "/home/ansible/JetPack/src/deploy/ocp_deployer/csah.py", line 299, in update_kickstart_usb
    tester = Checkpoints()
NameError: name 'Checkpoints' is not defined

2021-06-24 09:38:17,976 ERROR <class 'NameError'>
2021-06-24 09:39:10,722 INFO * Creating the SAH node usb image.
2021-06-24 09:39:10,723 DEBUG loading settings files /home/ansible/r87.ini
2021-06-24 09:39:10,732 INFO Settings .ini: /home/ansible/r87.ini
2021-06-24 09:39:10,732 INFO Settings .yaml /home/ansible/nodes.yaml
2021-06-24 09:39:10,732 ERROR Traceback (most recent call last):
  File "setup_usb_idrac.py", line 74, in setup
    sah.update_kickstart_usb()
  File "/home/ansible/JetPack/src/deploy/ocp_deployer/csah.py", line 300, in update_kickstart_usb
    tester = Checkpoints()
  File "/home/ansible/JetPack/src/deploy/ocp_deployer/checkpoints.py", line 31, in __init__
    self.director_ip = self.settings.director_node.public_api_ip
AttributeError: 'str' object has no attribute 'director_node'

2021-06-24 09:39:10,732 ERROR <class 'AttributeError'>
2021-06-24 09:39:35,283 INFO * Creating the SAH node usb image.
2021-06-24 09:39:35,284 DEBUG loading settings files /home/ansible/r87.ini
2021-06-24 09:39:35,293 INFO Settings .ini: /home/ansible/r87.ini
2021-06-24 09:39:35,293 INFO Settings .yaml /home/ansible/nodes.yaml
2021-06-24 09:39:35,293 ERROR Traceback (most recent call last):
  File "setup_usb_idrac.py", line 74, in setup
    sah.update_kickstart_usb()
  File "/home/ansible/JetPack/src/deploy/ocp_deployer/csah.py", line 303, in update_kickstart_usb
    shutil.copyfile(sets.csah_kickstart, sets.cloud_repo_dir +
AttributeError: 'OCP_Settings' object has no attribute 'csah_kickstart'

2021-06-24 09:39:35,293 ERROR <class 'AttributeError'>
2021-06-24 09:42:43,207 INFO * Creating the SAH node usb image.
2021-06-24 09:42:43,208 DEBUG loading settings files /home/ansible/r87.ini
2021-06-24 09:42:43,216 INFO Settings .ini: /home/ansible/r87.ini
2021-06-24 09:42:43,216 INFO Settings .yaml /home/ansible/nodes.yaml
2021-06-24 09:42:43,217 ERROR Traceback (most recent call last):
  File "setup_usb_idrac.py", line 74, in setup
    sah.update_kickstart_usb()
  File "/home/ansible/JetPack/src/deploy/ocp_deployer/csah.py", line 303, in update_kickstart_usb
    shutil.copyfile(sets.csah_kickstart, sets.cloud_repo_dir +
AttributeError: 'OCP_Settings' object has no attribute 'csah_kickstart'

2021-06-24 09:42:43,217 ERROR <class 'AttributeError'>
2021-06-24 09:46:45,837 INFO * Creating the SAH node usb image.
2021-06-24 09:46:45,838 DEBUG loading settings files /home/ansible/r87.ini
2021-06-24 09:46:45,847 INFO Settings .ini: /home/ansible/r87.ini
2021-06-24 09:46:45,847 INFO Settings .yaml /home/ansible/nodes.yaml
2021-06-24 09:46:45,873 ERROR Traceback (most recent call last):
  File "setup_usb_idrac.py", line 74, in setup
    sah.update_kickstart_usb()
  File "/home/ansible/JetPack/src/deploy/ocp_deployer/csah.py", line 304, in update_kickstart_usb
    "/../ocp-csah.ks")
  File "/usr/lib64/python3.6/shutil.py", line 120, in copyfile
    with open(src, 'rb') as fsrc:
FileNotFoundError: [Errno 2] No such file or directory: '/home/ansible/JetPacksrc/mgmt/ocp-csah.ks'

2021-06-24 09:46:45,873 ERROR <class 'FileNotFoundError'>
2021-06-24 09:47:06,984 INFO * Creating the SAH node usb image.
2021-06-24 09:47:06,986 DEBUG loading settings files /home/ansible/r87.ini
2021-06-24 09:47:06,994 INFO Settings .ini: /home/ansible/r87.ini
2021-06-24 09:47:06,994 INFO Settings .yaml /home/ansible/nodes.yaml
2021-06-24 09:47:06,995 ERROR Traceback (most recent call last):
  File "setup_usb_idrac.py", line 74, in setup
    sah.update_kickstart_usb()
  File "/home/ansible/JetPack/src/deploy/ocp_deployer/csah.py", line 306, in update_kickstart_usb
    FileHelper.replace_expression(sets.sah_kickstart,
NameError: name 'FileHelper' is not defined

2021-06-24 09:47:06,995 ERROR <class 'NameError'>
2021-06-24 09:48:01,477 INFO * Creating the SAH node usb image.
2021-06-24 09:48:01,479 DEBUG loading settings files /home/ansible/r87.ini
2021-06-24 09:48:01,487 INFO Settings .ini: /home/ansible/r87.ini
2021-06-24 09:48:01,487 INFO Settings .yaml /home/ansible/nodes.yaml
2021-06-24 09:48:01,488 ERROR Traceback (most recent call last):
  File "setup_usb_idrac.py", line 74, in setup
    sah.update_kickstart_usb()
  File "/home/ansible/JetPack/src/deploy/ocp_deployer/csah.py", line 306, in update_kickstart_usb
    FileHelper.replace_expression(sets.sah_kickstart,
AttributeError: 'OCP_Settings' object has no attribute 'sah_kickstart'

2021-06-24 09:48:01,488 ERROR <class 'AttributeError'>
2021-06-24 09:48:44,246 INFO * Creating the SAH node usb image.
2021-06-24 09:48:44,247 DEBUG loading settings files /home/ansible/r87.ini
2021-06-24 09:48:44,255 INFO Settings .ini: /home/ansible/r87.ini
2021-06-24 09:48:44,255 INFO Settings .yaml /home/ansible/nodes.yaml
2021-06-24 09:48:44,256 ERROR Traceback (most recent call last):
  File "setup_usb_idrac.py", line 74, in setup
    sah.update_kickstart_usb()
  File "/home/ansible/JetPack/src/deploy/ocp_deployer/csah.py", line 309, in update_kickstart_usb
    sets.csah_node.root_password +
AttributeError: 'OCP_node' object has no attribute 'root_password'

2021-06-24 09:48:44,256 ERROR <class 'AttributeError'>
2021-06-24 09:59:58,671 INFO * Creating the SAH node usb image.
2021-06-24 09:59:58,672 DEBUG loading settings files /home/ansible/r87.ini
2021-06-24 09:59:58,680 INFO Settings .ini: /home/ansible/r87.ini
2021-06-24 09:59:58,680 INFO Settings .yaml /home/ansible/nodes.yaml
2021-06-24 09:59:58,682 ERROR Traceback (most recent call last):
  File "setup_usb_idrac.py", line 74, in setup
    sah.update_kickstart_usb()
  File "/home/ansible/JetPack/src/deploy/ocp_deployer/csah.py", line 314, in update_kickstart_usb
    sets.ansible_password +
AttributeError: 'OCP_Settings' object has no attribute 'ansible_password'

2021-06-24 09:59:58,683 ERROR <class 'AttributeError'>
2021-06-24 10:02:24,324 INFO * Creating the SAH node usb image.
2021-06-24 10:02:24,325 DEBUG loading settings files /home/ansible/r87.ini
2021-06-24 10:02:24,333 INFO Settings .ini: /home/ansible/r87.ini
2021-06-24 10:02:24,333 INFO Settings .yaml /home/ansible/nodes.yaml
2021-06-24 10:02:24,340 ERROR Traceback (most recent call last):
  File "setup_usb_idrac.py", line 74, in setup
    sah.update_kickstart_usb()
  File "/home/ansible/JetPack/src/deploy/ocp_deployer/csah.py", line 329, in update_kickstart_usb
    sets.subscription_manager_pool_sah +
AttributeError: 'OCP_Settings' object has no attribute 'subscription_manager_pool_sah'

2021-06-24 10:02:24,340 ERROR <class 'AttributeError'>
2021-06-24 10:03:02,673 INFO * Creating the SAH node usb image.
2021-06-24 10:03:02,674 DEBUG loading settings files /home/ansible/r87.ini
2021-06-24 10:03:02,682 INFO Settings .ini: /home/ansible/r87.ini
2021-06-24 10:03:02,682 INFO Settings .yaml /home/ansible/nodes.yaml
2021-06-24 10:03:02,690 ERROR Traceback (most recent call last):
  File "setup_usb_idrac.py", line 74, in setup
    sah.update_kickstart_usb()
  File "/home/ansible/JetPack/src/deploy/ocp_deployer/csah.py", line 334, in update_kickstart_usb
    sets.public_api_gateway +
AttributeError: 'OCP_Settings' object has no attribute 'public_api_gateway'

2021-06-24 10:03:02,690 ERROR <class 'AttributeError'>
2021-06-24 10:17:29,114 INFO * Creating the SAH node usb image.
2021-06-24 10:17:29,115 DEBUG loading settings files /home/ansible/r87.ini
2021-06-24 10:17:29,124 INFO Settings .ini: /home/ansible/r87.ini
2021-06-24 10:17:29,124 INFO Settings .yaml /home/ansible/nodes.yaml
2021-06-24 10:17:29,131 ERROR Traceback (most recent call last):
  File "setup_usb_idrac.py", line 74, in setup
    sah.update_kickstart_usb()
  File "/home/ansible/JetPack/src/deploy/ocp_deployer/csah.py", line 334, in update_kickstart_usb
    sets.public_api_gateway +
AttributeError: 'OCP_Settings' object has no attribute 'public_api_gateway'

2021-06-24 10:17:29,131 ERROR <class 'AttributeError'>
2021-06-24 10:30:01,862 INFO * Creating the SAH node usb image.
2021-06-24 10:30:01,863 DEBUG loading settings files /home/ansible/r87.ini
2021-06-24 10:30:01,864 ERROR Traceback (most recent call last):
  File "setup_usb_idrac.py", line 65, in setup
    settings = Settings(args.settings)
  File "/home/ansible/JetPack/src/deploy/ocp_deployer/settings/ocp_config.py", line 76, in __init__
    self.gateway=network_settings['gateway']
KeyError: 'gateway'

2021-06-24 10:30:01,864 ERROR <class 'KeyError'>
2021-06-24 10:31:31,064 INFO * Creating the SAH node usb image.
2021-06-24 10:31:31,065 DEBUG loading settings files /home/ansible/r87.ini
2021-06-24 10:31:31,066 ERROR Traceback (most recent call last):
  File "setup_usb_idrac.py", line 65, in setup
    settings = Settings(args.settings)
  File "/home/ansible/JetPack/src/deploy/ocp_deployer/settings/ocp_config.py", line 77, in __init__
    self.ntp=network_settings['ntp_server']
KeyError: 'ntp_server'

2021-06-24 10:31:31,066 ERROR <class 'KeyError'>
2021-06-24 10:33:34,093 INFO * Creating the SAH node usb image.
2021-06-24 10:33:34,094 DEBUG loading settings files /home/ansible/r87.ini
2021-06-24 10:33:34,095 ERROR Traceback (most recent call last):
  File "setup_usb_idrac.py", line 65, in setup
    settings = Settings(args.settings)
  File "/home/ansible/JetPack/src/deploy/ocp_deployer/settings/ocp_config.py", line 76, in __init__
    self.gateway = network_settings['gateway']
KeyError: 'gateway'

2021-06-24 10:33:34,095 ERROR <class 'KeyError'>
2021-06-24 10:34:46,946 INFO * Creating the SAH node usb image.
2021-06-24 10:34:46,947 DEBUG loading settings files /home/ansible/r87.ini
2021-06-24 10:34:46,948 ERROR Traceback (most recent call last):
  File "setup_usb_idrac.py", line 65, in setup
    settings = Settings(args.settings)
  File "/home/ansible/JetPack/src/deploy/ocp_deployer/settings/ocp_config.py", line 76, in __init__
    self.gggateway = network_settings['gateway']
KeyError: 'gateway'

2021-06-24 10:34:46,948 ERROR <class 'KeyError'>
2021-06-24 10:34:57,401 INFO * Creating the SAH node usb image.
2021-06-24 10:34:57,402 DEBUG loading settings files /home/ansible/r87.ini
2021-06-24 10:34:57,403 ERROR Traceback (most recent call last):
  File "setup_usb_idrac.py", line 65, in setup
    settings = Settings(args.settings)
  File "/home/ansible/JetPack/src/deploy/ocp_deployer/settings/ocp_config.py", line 76, in __init__
    self.gggateway = network_settings['gateway']
KeyError: 'gateway'

2021-06-24 10:34:57,404 ERROR <class 'KeyError'>
2021-06-24 10:35:25,352 INFO * Creating the SAH node usb image.
2021-06-24 10:35:25,353 DEBUG loading settings files /home/ansible/r87.ini
2021-06-24 10:35:25,354 ERROR Traceback (most recent call last):
  File "setup_usb_idrac.py", line 65, in setup
    settings = Settings(args.settings)
  File "/home/ansible/JetPack/src/deploy/ocp_deployer/settings/ocp_config.py", line 76, in __init__
    self.gateway = network_settings['gadsteway']
KeyError: 'gadsteway'

2021-06-24 10:35:25,354 ERROR <class 'KeyError'>
2021-06-24 10:36:21,146 INFO * Creating the SAH node usb image.
2021-06-24 10:36:21,147 DEBUG loading settings files /home/ansible/r87.ini
2021-06-24 10:36:21,149 ERROR Traceback (most recent call last):
  File "setup_usb_idrac.py", line 65, in setup
    settings = Settings(args.settings)
  File "/home/ansible/JetPack/src/deploy/ocp_deployer/settings/ocp_config.py", line 76, in __init__
    self.gateway = network_settings['gateway']
KeyError: 'gateway'

2021-06-24 10:36:21,149 ERROR <class 'KeyError'>
2021-06-24 10:47:14,517 INFO * Creating the SAH node usb image.
2021-06-24 10:47:14,519 DEBUG loading settings files /home/ansible/r87.ini
2021-06-24 10:47:14,520 ERROR Traceback (most recent call last):
  File "setup_usb_idrac.py", line 65, in setup
    settings = Settings(args.settings)
  File "/home/ansible/JetPack/src/deploy/ocp_deployer/settings/ocp_config.py", line 76, in __init__
    self.gateway = network_settings['gateway']
KeyError: 'gateway'

2021-06-24 10:47:14,520 ERROR <class 'KeyError'>
2021-06-24 10:50:18,094 INFO * Creating the SAH node usb image.
2021-06-24 10:50:18,096 DEBUG loading settings files /home/ansible/r87.ini
2021-06-24 10:50:18,104 INFO Settings .ini: /home/ansible/r87.ini
2021-06-24 10:50:18,104 INFO Settings .yaml /home/ansible/nodes.yaml
2021-06-24 10:50:18,113 ERROR Traceback (most recent call last):
  File "setup_usb_idrac.py", line 74, in setup
    sah.update_kickstart_usb()
  File "/home/ansible/JetPack/src/deploy/ocp_deployer/csah.py", line 339, in update_kickstart_usb
    sets.name_server +
AttributeError: 'OCP_Settings' object has no attribute 'name_server'

2021-06-24 10:50:18,113 ERROR <class 'AttributeError'>
2021-06-24 10:52:41,013 INFO * Creating the SAH node usb image.
2021-06-24 10:52:41,014 DEBUG loading settings files /home/ansible/r87.ini
2021-06-24 10:52:41,023 INFO Settings .ini: /home/ansible/r87.ini
2021-06-24 10:52:41,023 INFO Settings .yaml /home/ansible/nodes.yaml
2021-06-24 10:52:41,032 ERROR Traceback (most recent call last):
  File "setup_usb_idrac.py", line 74, in setup
    sah.update_kickstart_usb()
  File "/home/ansible/JetPack/src/deploy/ocp_deployer/csah.py", line 339, in update_kickstart_usb
    sets.name_server +
AttributeError: 'OCP_Settings' object has no attribute 'name_server'

2021-06-24 10:52:41,032 ERROR <class 'AttributeError'>
2021-06-24 10:53:28,310 INFO * Creating the SAH node usb image.
2021-06-24 10:53:28,311 DEBUG loading settings files /home/ansible/r87.ini
2021-06-24 10:53:28,320 INFO Settings .ini: /home/ansible/r87.ini
2021-06-24 10:53:28,320 INFO Settings .yaml /home/ansible/nodes.yaml
2021-06-24 10:53:28,330 ERROR Traceback (most recent call last):
  File "setup_usb_idrac.py", line 74, in setup
    sah.update_kickstart_usb()
  File "/home/ansible/JetPack/src/deploy/ocp_deployer/csah.py", line 344, in update_kickstart_usb
    sets.ntp_server +
AttributeError: 'OCP_Settings' object has no attribute 'ntp_server'

2021-06-24 10:53:28,330 ERROR <class 'AttributeError'>
2021-06-24 10:53:46,270 INFO * Creating the SAH node usb image.
2021-06-24 10:53:46,272 DEBUG loading settings files /home/ansible/r87.ini
2021-06-24 10:53:46,280 INFO Settings .ini: /home/ansible/r87.ini
2021-06-24 10:53:46,280 INFO Settings .yaml /home/ansible/nodes.yaml
2021-06-24 10:53:46,307 ERROR Traceback (most recent call last):
  File "setup_usb_idrac.py", line 74, in setup
    sah.update_kickstart_usb()
  File "/home/ansible/JetPack/src/deploy/ocp_deployer/csah.py", line 404, in update_kickstart_usb
    if sets.use_satellite is True:
AttributeError: 'OCP_Settings' object has no attribute 'use_satellite'

2021-06-24 10:53:46,307 ERROR <class 'AttributeError'>
2021-06-24 10:55:04,652 INFO * Creating the SAH node usb image.
2021-06-24 10:55:04,653 DEBUG loading settings files /home/ansible/r87.ini
2021-06-24 10:55:04,662 INFO Settings .ini: /home/ansible/r87.ini
2021-06-24 10:55:04,662 INFO Settings .yaml /home/ansible/nodes.yaml
2021-06-24 10:55:04,689 ERROR Traceback (most recent call last):
  File "setup_usb_idrac.py", line 74, in setup
    sah.update_kickstart_usb()
  File "/home/ansible/JetPack/src/deploy/ocp_deployer/csah.py", line 404, in update_kickstart_usb
    if sets.use_satellite is True:
AttributeError: 'OCP_Settings' object has no attribute 'use_satellite'

2021-06-24 10:55:04,689 ERROR <class 'AttributeError'>
2021-06-24 10:56:14,637 INFO * Creating the SAH node usb image.
2021-06-24 10:56:14,639 DEBUG loading settings files /home/ansible/r87.ini
2021-06-24 10:56:14,647 INFO Settings .ini: /home/ansible/r87.ini
2021-06-24 10:56:14,647 INFO Settings .yaml /home/ansible/nodes.yaml
2021-06-24 10:56:17,676 ERROR Traceback (most recent call last):
  File "setup_usb_idrac.py", line 88, in setup
    'cd ~;cp ' + settings.network_conf + ' /mnt/usb',
AttributeError: 'OCP_Settings' object has no attribute 'network_conf'

2021-06-24 10:56:17,676 ERROR <class 'AttributeError'>
2021-06-24 10:58:42,810 INFO * Creating the SAH node usb image.
2021-06-24 10:58:42,811 DEBUG loading settings files /home/ansible/r87.ini
2021-06-24 10:58:42,820 INFO Settings .ini: /home/ansible/r87.ini
2021-06-24 10:58:42,820 INFO Settings .yaml /home/ansible/nodes.yaml
2021-06-24 10:58:45,849 DEBUG running cd ~;rm -f ocp_ks.img
2021-06-24 10:58:45,853 DEBUG b''
2021-06-24 10:58:45,854 DEBUG running cd ~;dd if=/dev/zero of=osp_ks.img bs=1M count=10000
2021-06-24 10:59:13,534 DEBUG b'10000+0 records in\n10000+0 records out\n10485760000 bytes (10 GB, 9.8 GiB) copied, 27.6567 s, 379 MB/s\n'
2021-06-24 10:59:13,537 DEBUG running cd ~;mkfs ext3 -F ocp_ks.img
2021-06-24 10:59:21,137 ERROR Traceback (most recent call last):
  File "setup_usb_idrac.py", line 109, in setup
    shell=True))
  File "/usr/lib64/python3.6/subprocess.py", line 356, in check_output
    **kwargs).stdout
  File "/usr/lib64/python3.6/subprocess.py", line 438, in run
    output=stdout, stderr=stderr)
subprocess.CalledProcessError: Command 'cd ~;mkfs ext3 -F ocp_ks.img' returned non-zero exit status 1.

2021-06-24 10:59:21,138 ERROR <class 'subprocess.CalledProcessError'>
2021-06-24 11:00:57,333 INFO * Creating the SAH node usb image.
2021-06-24 11:00:57,334 DEBUG loading settings files /home/ansible/r87.ini
2021-06-24 11:00:57,343 INFO Settings .ini: /home/ansible/r87.ini
2021-06-24 11:00:57,343 INFO Settings .yaml /home/ansible/nodes.yaml
2021-06-24 11:01:00,373 DEBUG running cd ~;rm -f ocp_ks.img
2021-06-24 11:01:00,377 DEBUG b''
2021-06-24 11:01:00,377 DEBUG running cd ~;dd if=/dev/zero of=ocp_ks.img bs=1M count=10000
2021-06-24 11:01:29,233 DEBUG b'10000+0 records in\n10000+0 records out\n10485760000 bytes (10 GB, 9.8 GiB) copied, 28.837 s, 364 MB/s\n'
2021-06-24 11:01:29,421 DEBUG running cd ~;mkfs ext3 -F ocp_ks.img
2021-06-24 11:01:42,502 DEBUG b'mke2fs 1.45.6 (20-Mar-2020)\nDiscarding device blocks:    4096/2560000\x08\x08\x08\x08\x08\x08\x08\x08\x08\x08\x08\x08\x08\x08\x081052672/2560000\x08\x08\x08\x08\x08\x08\x08\x08\x08\x08\x08\x08\x08\x08\x08               \x08\x08\x08\x08\x08\x08\x08\x08\x08\x08\x08\x08\x08\x08\x08done                            \nCreating filesystem with 2560000 4k blocks and 640848 inodes\nFilesystem UUID: fc0e5002-bd06-4bed-aa81-2f5a636aa355\nSuperblock backups stored on blocks: \n\t32768, 98304, 163840, 229376, 294912, 819200, 884736, 1605632\n\nAllocating group tables:  0/79\x08\x08\x08\x08\x08     \x08\x08\x08\x08\x08done                            \nWriting inode tables:  0/79\x08\x08\x08\x08\x08     \x08\x08\x08\x08\x08done                            \nWriting superblocks and filesystem accounting information:  0/79\x08\x08\x08\x08\x08     \x08\x08\x08\x08\x08done\n\n'
2021-06-24 11:01:42,502 DEBUG running mkdir -p /mnt/usb
2021-06-24 11:01:42,506 DEBUG b''
2021-06-24 11:01:42,507 DEBUG running cd ~;mount -o loop ocp_ks.img /mnt/usb
2021-06-24 11:01:42,602 ERROR Traceback (most recent call last):
  File "setup_usb_idrac.py", line 109, in setup
    shell=True))
  File "/usr/lib64/python3.6/subprocess.py", line 356, in check_output
    **kwargs).stdout
  File "/usr/lib64/python3.6/subprocess.py", line 438, in run
    output=stdout, stderr=stderr)
subprocess.CalledProcessError: Command 'cd ~;mount -o loop ocp_ks.img /mnt/usb' returned non-zero exit status 1.

2021-06-24 11:01:42,602 ERROR <class 'subprocess.CalledProcessError'>
2021-06-24 11:03:04,379 INFO * Creating the SAH node usb image.
2021-06-24 11:03:04,381 DEBUG loading settings files /home/ansible/r87.ini
2021-06-24 11:03:04,389 INFO Settings .ini: /home/ansible/r87.ini
2021-06-24 11:03:04,389 INFO Settings .yaml /home/ansible/nodes.yaml
2021-06-24 11:03:07,419 DEBUG running cd ~;rm -f ocp_ks.img
2021-06-24 11:03:07,424 DEBUG b''
2021-06-24 11:03:07,424 DEBUG running cd ~;dd if=/dev/zero of=ocp_ks.img bs=1M count=10000
2021-06-24 11:03:34,854 DEBUG b'10000+0 records in\n10000+0 records out\n10485760000 bytes (10 GB, 9.8 GiB) copied, 27.4255 s, 382 MB/s\n'
2021-06-24 11:03:35,041 DEBUG running cd ~;mkfs ext3 -F ocp_ks.img
2021-06-24 11:03:48,144 DEBUG b'mke2fs 1.45.6 (20-Mar-2020)\nDiscarding device blocks:    4096/2560000\x08\x08\x08\x08\x08\x08\x08\x08\x08\x08\x08\x08\x08\x08\x08               \x08\x08\x08\x08\x08\x08\x08\x08\x08\x08\x08\x08\x08\x08\x08done                            \nCreating filesystem with 2560000 4k blocks and 640848 inodes\nFilesystem UUID: 53ca9469-e85c-48e1-a161-a33440e518f2\nSuperblock backups stored on blocks: \n\t32768, 98304, 163840, 229376, 294912, 819200, 884736, 1605632\n\nAllocating group tables:  0/79\x08\x08\x08\x08\x08     \x08\x08\x08\x08\x08done                            \nWriting inode tables:  0/79\x08\x08\x08\x08\x08     \x08\x08\x08\x08\x08done                            \nWriting superblocks and filesystem accounting information:  0/79\x08\x08\x08\x08\x08     \x08\x08\x08\x08\x08done\n\n'
2021-06-24 11:03:48,144 DEBUG running mkdir -p /mnt/usb
2021-06-24 11:03:48,149 DEBUG b''
2021-06-24 11:03:48,149 DEBUG running cd ~;mount -o loop ocp_ks.img /mnt/usb
2021-06-24 11:03:48,327 ERROR Traceback (most recent call last):
  File "setup_usb_idrac.py", line 109, in setup
    shell=True))
  File "/usr/lib64/python3.6/subprocess.py", line 356, in check_output
    **kwargs).stdout
  File "/usr/lib64/python3.6/subprocess.py", line 438, in run
    output=stdout, stderr=stderr)
subprocess.CalledProcessError: Command 'cd ~;mount -o loop ocp_ks.img /mnt/usb' returned non-zero exit status 1.

2021-06-24 11:03:48,328 ERROR <class 'subprocess.CalledProcessError'>
2021-06-24 11:13:11,253 INFO * Creating the SAH node usb image.
2021-06-24 11:13:11,255 DEBUG loading settings files /root/r87.ini
2021-06-24 11:13:11,255 ERROR Traceback (most recent call last):
  File "setup_usb_idrac.py", line 65, in setup
    settings = Settings(args.settings)
  File "/root/ansible/JetPack/src/deploy/ocp_deployer/settings/ocp_config.py", line 31, in __init__
    settings_file), settings_file + " file does not exist"
AssertionError: /root/r87.ini file does not exist

2021-06-24 11:13:11,255 ERROR <class 'AssertionError'>
2021-06-24 11:13:17,607 INFO * Creating the SAH node usb image.
2021-06-24 11:13:17,608 DEBUG loading settings files /root/ansible/r87.ini
2021-06-24 11:13:17,617 INFO Settings .ini: /root/ansible/r87.ini
2021-06-24 11:13:17,617 INFO Settings .yaml /home/ansible/nodes.yaml
2021-06-24 11:13:20,646 DEBUG running cd ~;rm -f ocp_ks.img
2021-06-24 11:13:21,254 DEBUG b''
2021-06-24 11:13:21,254 DEBUG running cd ~;dd if=/dev/zero of=ocp_ks.img bs=1M count=10000
2021-06-24 11:13:50,580 DEBUG b'10000+0 records in\n10000+0 records out\n10485760000 bytes (10 GB, 9.8 GiB) copied, 29.3218 s, 358 MB/s\n'
2021-06-24 11:13:50,580 DEBUG running cd ~;mkfs ext3 -F ocp_ks.img
2021-06-24 11:14:05,115 DEBUG b'mke2fs 1.45.6 (20-Mar-2020)\nDiscarding device blocks:    4096/2560000\x08\x08\x08\x08\x08\x08\x08\x08\x08\x08\x08\x08\x08\x08\x08               \x08\x08\x08\x08\x08\x08\x08\x08\x08\x08\x08\x08\x08\x08\x08done                            \nCreating filesystem with 2560000 4k blocks and 640848 inodes\nFilesystem UUID: 73097190-4090-4d85-91b2-80f46763e8e8\nSuperblock backups stored on blocks: \n\t32768, 98304, 163840, 229376, 294912, 819200, 884736, 1605632\n\nAllocating group tables:  0/79\x08\x08\x08\x08\x08     \x08\x08\x08\x08\x08done                            \nWriting inode tables:  0/79\x08\x08\x08\x08\x08     \x08\x08\x08\x08\x08done                            \nWriting superblocks and filesystem accounting information:  0/79\x08\x08\x08\x08\x08     \x08\x08\x08\x08\x08done\n\n'
2021-06-24 11:14:05,115 DEBUG running mkdir -p /mnt/usb
2021-06-24 11:14:05,119 DEBUG b''
2021-06-24 11:14:05,119 DEBUG running cd ~;mount -o loop ocp_ks.img /mnt/usb
2021-06-24 11:14:05,138 DEBUG b''
2021-06-24 11:14:05,138 DEBUG running cd ~;cp -R ~/ansible /mnt/usb
2021-06-24 11:14:05,856 DEBUG b''
2021-06-24 11:14:05,856 DEBUG running cd ~;cp /home/ansible/rhel82.iso /mnt/usb
2021-06-24 11:14:06,559 DEBUG b''
2021-06-24 11:14:06,559 DEBUG running cd ~;cp /root/ansible/r87.ini /mnt/usb
2021-06-24 11:14:06,563 DEBUG b''
2021-06-24 11:14:06,563 DEBUG running cd ~;cp /home/ansible/nodes.yaml /mnt/usb
2021-06-24 11:14:06,567 DEBUG b''
2021-06-24 11:14:06,567 DEBUG running cd ~;cp ocp-sah.ks /mnt/usb
2021-06-24 11:14:06,572 ERROR Traceback (most recent call last):
  File "setup_usb_idrac.py", line 109, in setup
    shell=True))
  File "/usr/lib64/python3.6/subprocess.py", line 356, in check_output
    **kwargs).stdout
  File "/usr/lib64/python3.6/subprocess.py", line 438, in run
    output=stdout, stderr=stderr)
subprocess.CalledProcessError: Command 'cd ~;cp ocp-sah.ks /mnt/usb' returned non-zero exit status 1.

2021-06-24 11:14:06,572 ERROR <class 'subprocess.CalledProcessError'>
2021-06-24 11:19:11,980 INFO * Creating the SAH node usb image.
2021-06-24 11:19:11,982 DEBUG loading settings files /root/ansible/r87.ini
2021-06-24 11:19:11,990 INFO Settings .ini: /root/ansible/r87.ini
2021-06-24 11:19:11,990 INFO Settings .yaml /home/ansible/nodes.yaml
2021-06-24 11:19:15,019 DEBUG running cd ~;rm -f ocp_ks.img
2021-06-24 11:19:15,023 DEBUG b''
2021-06-24 11:19:15,024 DEBUG running cd ~;dd if=/dev/zero of=ocp_ks.img bs=1M count=10000
2021-06-24 11:19:44,125 DEBUG b'10000+0 records in\n10000+0 records out\n10485760000 bytes (10 GB, 9.8 GiB) copied, 29.0969 s, 360 MB/s\n'
2021-06-24 11:19:45,203 DEBUG running cd ~;mkfs ext3 -F ocp_ks.img
2021-06-24 11:19:58,895 DEBUG b'mke2fs 1.45.6 (20-Mar-2020)\nDiscarding device blocks:    4096/2560000\x08\x08\x08\x08\x08\x08\x08\x08\x08\x08\x08\x08\x08\x08\x08               \x08\x08\x08\x08\x08\x08\x08\x08\x08\x08\x08\x08\x08\x08\x08done                            \nCreating filesystem with 2560000 4k blocks and 640848 inodes\nFilesystem UUID: 12705abb-9eda-4783-b33c-f03bb06a7285\nSuperblock backups stored on blocks: \n\t32768, 98304, 163840, 229376, 294912, 819200, 884736, 1605632\n\nAllocating group tables:  0/79\x08\x08\x08\x08\x08     \x08\x08\x08\x08\x08done                            \nWriting inode tables:  0/79\x08\x08\x08\x08\x08     \x08\x08\x08\x08\x08done                            \nWriting superblocks and filesystem accounting information:  0/79\x08\x08\x08\x08\x08     \x08\x08\x08\x08\x08done\n\n'
2021-06-24 11:19:58,896 DEBUG running mkdir -p /mnt/usb
2021-06-24 11:19:58,899 DEBUG b''
2021-06-24 11:19:58,899 DEBUG running cd ~;mount -o loop ocp_ks.img /mnt/usb
2021-06-24 11:19:58,932 DEBUG b''
2021-06-24 11:19:58,932 DEBUG running cd ~;cp -R ~/ansible /mnt/usb
2021-06-24 11:20:02,469 DEBUG b''
2021-06-24 11:20:02,469 DEBUG running cd ~;cp /home/ansible/rhel82.iso /mnt/usb
2021-06-24 11:20:03,144 DEBUG b''
2021-06-24 11:20:03,144 DEBUG running cd ~;cp /root/ansible/r87.ini /mnt/usb
2021-06-24 11:20:03,149 DEBUG b''
2021-06-24 11:20:03,149 DEBUG running cd ~;cp /home/ansible/nodes.yaml /mnt/usb
2021-06-24 11:20:03,153 DEBUG b''
2021-06-24 11:20:03,153 DEBUG running cd ~;cp ocp-sah.ks /mnt/usb
2021-06-24 11:20:03,157 ERROR Traceback (most recent call last):
  File "setup_usb_idrac.py", line 109, in setup
    shell=True))
  File "/usr/lib64/python3.6/subprocess.py", line 356, in check_output
    **kwargs).stdout
  File "/usr/lib64/python3.6/subprocess.py", line 438, in run
    output=stdout, stderr=stderr)
subprocess.CalledProcessError: Command 'cd ~;cp ocp-sah.ks /mnt/usb' returned non-zero exit status 1.

2021-06-24 11:20:03,158 ERROR <class 'subprocess.CalledProcessError'>
2021-06-24 11:23:40,901 INFO * Creating the SAH node usb image.
2021-06-24 11:23:40,903 DEBUG loading settings files /root/ansible/r87.ini
2021-06-24 11:23:40,911 INFO Settings .ini: /root/ansible/r87.ini
2021-06-24 11:23:40,911 INFO Settings .yaml /home/ansible/nodes.yaml
2021-06-24 11:23:43,940 DEBUG running cd ~;rm -f ocp_ks.img
2021-06-24 11:23:43,944 DEBUG b''
2021-06-24 11:23:43,944 DEBUG running cd ~;dd if=/dev/zero of=ocp_ks.img bs=1M count=10000
2021-06-24 11:24:12,620 DEBUG b'10000+0 records in\n10000+0 records out\n10485760000 bytes (10 GB, 9.8 GiB) copied, 28.6721 s, 366 MB/s\n'
2021-06-24 11:24:12,689 DEBUG running cd ~;mkfs ext3 -F ocp_ks.img
2021-06-24 11:24:27,338 DEBUG b'mke2fs 1.45.6 (20-Mar-2020)\nDiscarding device blocks:    4096/2560000\x08\x08\x08\x08\x08\x08\x08\x08\x08\x08\x08\x08\x08\x08\x081576960/2560000\x08\x08\x08\x08\x08\x08\x08\x08\x08\x08\x08\x08\x08\x08\x08               \x08\x08\x08\x08\x08\x08\x08\x08\x08\x08\x08\x08\x08\x08\x08done                            \nCreating filesystem with 2560000 4k blocks and 640848 inodes\nFilesystem UUID: eefdca4e-bf80-4a69-9ea9-7b5324eb6a55\nSuperblock backups stored on blocks: \n\t32768, 98304, 163840, 229376, 294912, 819200, 884736, 1605632\n\nAllocating group tables:  0/79\x08\x08\x08\x08\x08     \x08\x08\x08\x08\x08done                            \nWriting inode tables:  0/79\x08\x08\x08\x08\x08     \x08\x08\x08\x08\x08done                            \nWriting superblocks and filesystem accounting information:  0/79\x08\x08\x08\x08\x08     \x08\x08\x08\x08\x08done\n\n'
2021-06-24 11:24:27,338 DEBUG running mkdir -p /mnt/usb
2021-06-24 11:24:27,342 DEBUG b''
2021-06-24 11:24:27,342 DEBUG running cd ~;mount -o loop ocp_ks.img /mnt/usb
2021-06-24 11:24:27,369 DEBUG b''
2021-06-24 11:24:27,369 DEBUG running cd ~;cp -R ~/ansible /mnt/usb
2021-06-24 11:24:28,246 DEBUG b''
2021-06-24 11:24:28,246 DEBUG running cd ~;cp /home/ansible/rhel82.iso /mnt/usb
2021-06-24 11:24:28,920 DEBUG b''
2021-06-24 11:24:28,920 DEBUG running cd ~;cp /root/ansible/r87.ini /mnt/usb
2021-06-24 11:24:28,924 DEBUG b''
2021-06-24 11:24:28,924 DEBUG running cd ~;cp /home/ansible/nodes.yaml /mnt/usb
2021-06-24 11:24:28,928 DEBUG b''
2021-06-24 11:24:28,928 DEBUG running cd ~;cp ocp-sah.ks /mnt/usb
2021-06-24 11:24:28,933 ERROR Traceback (most recent call last):
  File "setup_usb_idrac.py", line 109, in setup
    shell=True))
  File "/usr/lib64/python3.6/subprocess.py", line 356, in check_output
    **kwargs).stdout
  File "/usr/lib64/python3.6/subprocess.py", line 438, in run
    output=stdout, stderr=stderr)
subprocess.CalledProcessError: Command 'cd ~;cp ocp-sah.ks /mnt/usb' returned non-zero exit status 1.

2021-06-24 11:24:28,933 ERROR <class 'subprocess.CalledProcessError'>
2021-06-24 11:56:28,747 INFO * Creating the SAH node usb image.
2021-06-24 11:56:28,749 DEBUG loading settings files /root/ansible/r87.ini
2021-06-24 11:56:28,758 INFO Settings .ini: /root/ansible/r87.ini
2021-06-24 11:56:28,758 INFO Settings .yaml /home/ansible/nodes.yaml
2021-06-24 11:56:28,758 ERROR Traceback (most recent call last):
  File "setup_usb_idrac.py", line 74, in setup
    sah.update_kickstart_usb()
  File "/root/ansible/JetPack/src/deploy/ocp_deployer/csah.py", line 310, in update_kickstart_usb
    '"')
  File "/root/ansible/JetPack/src/deploy/auto_common/file_utils.py", line 25, in replace_expression
    fh = open(fileref, 'r')
FileNotFoundError: [Errno 2] No such file or directory: '/root/ansible/JetPack/../ocp-csah.ks'

2021-06-24 11:56:28,759 ERROR <class 'FileNotFoundError'>
2021-06-24 11:59:13,870 INFO * Creating the SAH node usb image.
2021-06-24 11:59:13,871 DEBUG loading settings files /root/ansible/r87.ini
2021-06-24 11:59:13,880 INFO Settings .ini: /root/ansible/r87.ini
2021-06-24 11:59:13,880 INFO Settings .yaml /home/ansible/nodes.yaml
2021-06-24 11:59:13,881 ERROR Traceback (most recent call last):
  File "setup_usb_idrac.py", line 74, in setup
    sah.update_kickstart_usb()
  File "/root/ansible/JetPack/src/deploy/ocp_deployer/csah.py", line 310, in update_kickstart_usb
    '"')
  File "/root/ansible/JetPack/src/deploy/auto_common/file_utils.py", line 25, in replace_expression
    fh = open(fileref, 'r')
FileNotFoundError: [Errno 2] No such file or directory: '/root/ansible/JetPack/../ocp-csah.ks'

2021-06-24 11:59:13,881 ERROR <class 'FileNotFoundError'>
2021-06-24 12:01:03,233 INFO * Creating the SAH node usb image.
2021-06-24 12:01:03,234 DEBUG loading settings files /root/ansible/r87.ini
2021-06-24 12:01:03,243 INFO Settings .ini: /root/ansible/r87.ini
2021-06-24 12:01:03,243 INFO Settings .yaml /home/ansible/nodes.yaml
2021-06-24 12:01:06,273 DEBUG running cd ~;rm -f ocp_ks.img
2021-06-24 12:01:06,277 DEBUG b''
2021-06-24 12:01:06,277 DEBUG running cd ~;dd if=/dev/zero of=ocp_ks.img bs=1M count=10000
2021-06-24 12:01:34,752 DEBUG b'10000+0 records in\n10000+0 records out\n10485760000 bytes (10 GB, 9.8 GiB) copied, 28.471 s, 368 MB/s\n'
2021-06-24 12:01:34,877 DEBUG running cd ~;mkfs ext3 -F ocp_ks.img
2021-06-24 12:01:49,629 DEBUG b'mke2fs 1.45.6 (20-Mar-2020)\nDiscarding device blocks:    4096/2560000\x08\x08\x08\x08\x08\x08\x08\x08\x08\x08\x08\x08\x08\x08\x081052672/2560000\x08\x08\x08\x08\x08\x08\x08\x08\x08\x08\x08\x08\x08\x08\x08               \x08\x08\x08\x08\x08\x08\x08\x08\x08\x08\x08\x08\x08\x08\x08done                            \nCreating filesystem with 2560000 4k blocks and 640848 inodes\nFilesystem UUID: d6ff89bb-d2fe-4788-94a8-a7a4f1f3210f\nSuperblock backups stored on blocks: \n\t32768, 98304, 163840, 229376, 294912, 819200, 884736, 1605632\n\nAllocating group tables:  0/79\x08\x08\x08\x08\x08     \x08\x08\x08\x08\x08done                            \nWriting inode tables:  0/79\x08\x08\x08\x08\x08     \x08\x08\x08\x08\x08done                            \nWriting superblocks and filesystem accounting information:  0/79\x08\x08\x08\x08\x08     \x08\x08\x08\x08\x08done\n\n'
2021-06-24 12:01:49,629 DEBUG running mkdir -p /mnt/usb
2021-06-24 12:01:49,633 DEBUG b''
2021-06-24 12:01:49,633 DEBUG running cd ~;mount -o loop ocp_ks.img /mnt/usb
2021-06-24 12:01:49,668 DEBUG b''
2021-06-24 12:01:49,668 DEBUG running cd ~;cp -R ~/ansible /mnt/usb
2021-06-24 12:01:50,412 DEBUG b''
2021-06-24 12:01:50,412 DEBUG running cd ~;cp /home/ansible/rhel82.iso /mnt/usb
2021-06-24 12:01:51,076 DEBUG b''
2021-06-24 12:01:51,076 DEBUG running cd ~;cp /root/ansible/r87.ini /mnt/usb
2021-06-24 12:01:51,081 DEBUG b''
2021-06-24 12:01:51,081 DEBUG running cd ~;cp /home/ansible/nodes.yaml /mnt/usb
2021-06-24 12:01:51,085 DEBUG b''
2021-06-24 12:01:51,085 DEBUG running cd ~;cp ocp-sah.ks /mnt/usb
2021-06-24 12:01:51,089 ERROR Traceback (most recent call last):
  File "setup_usb_idrac.py", line 109, in setup
    shell=True))
  File "/usr/lib64/python3.6/subprocess.py", line 356, in check_output
    **kwargs).stdout
  File "/usr/lib64/python3.6/subprocess.py", line 438, in run
    output=stdout, stderr=stderr)
subprocess.CalledProcessError: Command 'cd ~;cp ocp-sah.ks /mnt/usb' returned non-zero exit status 1.

2021-06-24 12:01:51,090 ERROR <class 'subprocess.CalledProcessError'>
